<?xml version="1.0" encoding="utf-8"?>
<!-- This URDF was automatically created by SolidWorks to URDF Exporter! Originally created by Stephen Brawner (brawner@gmail.com) 
     Commit Version: 1.6.0-1-g15f4949  Build Version: 1.6.7594.29634
     For more information, please see http://wiki.ros.org/sw_urdf_exporter 
	https://answers.ros.org/question/243910/easily-move-relative-base-position-in-urdf-for-2-seperate-robots/-->

<robot
  name="scara">

  <link name="world" />

  <link
    name="base_link">
    <visual>
      <origin
        xyz="0 0 0"
        rpy="0 0 0" />
      <geometry>
        <mesh
          filename="file:~/scara_description_symlink/base_link.STL" /> 
      </geometry>
      <material
        name="">
        <color
          rgba="0.792156862745098 0.819607843137255 0.933333333333333 1" />
      </material>
    </visual>
    <collision>
      <origin
        xyz="0 0 0"
        rpy="0 0 0" />
      <geometry>
        <mesh
          filename="file:///home/ben/scara_ws/src/scara_description/base_link.STL" />
      </geometry>
    </collision>
  </link>

  <joint
    name="offset"
    type="fixed">
    <origin
      xyz="0.1 0.1 -0.12"
      rpy="0 0 0" />
    <parent
      link="world" />
    <child
      link="base_link" />
    <axis
      xyz="0 1 0" />
  </joint>

  <link
    name="ZL">
    <visual>
      <origin
        xyz="0 0 0"
        rpy="0 0 0" />
      <geometry>
        <mesh
          filename="file:///home/ben/scara_ws/src/scara_description/ZL.STL" />
      </geometry>
      <material
        name="">
        <color
          rgba="0.792156862745098 0.819607843137255 0.933333333333333 1" />
      </material>
    </visual>
    <collision>
      <origin
        xyz="0 0 0"
        rpy="0 0 0" />
      <geometry>
        <mesh
          filename="file:///home/ben/scara_ws/src/scara_description/ZL.STL" />
      </geometry>
    </collision>
  </link>

  <joint
    name="ZJ"
    type="prismatic">
    <origin
      xyz="-0.10866 -0.075122 0.19155"
      rpy="1.5708 0 0" />
    <parent
      link="base_link" />
    <child
      link="ZL" />
    <axis
      xyz="0 1 0" />
<limit effort="1000.0" lower="0" upper="0.22" velocity="1"/>
  </joint>

  <link
    name="XL">
    <visual>
      <origin
        xyz="0 0 0"
        rpy="0 0 0" />
      <geometry>
        <mesh
          filename="file:///home/ben/scara_ws/src/scara_description/XL.STL" />
      </geometry>
      <material
        name="">
        <color
          rgba="0.792156862745098 0.819607843137255 0.933333333333333 1" />
      </material>
    </visual>
    <collision>
      <origin
        xyz="0 0 0"
        rpy="0 0 0" />
      <geometry>
        <mesh
          filename="file:///home/ben/scara_ws/src/scara_description/XL.STL" />
      </geometry>
    </collision>
  </link>

  <joint
    name="XJ"
    type="revolute">
    <origin
      xyz="-0.045996 0 -0.042"
      rpy="3.1416 -0.065872 3.1416" />
    <parent
      link="ZL" />
    <child
      link="XL" />
    <axis
      xyz="0 1 0" />
   <limit effort="1000.0" lower="-4.5" upper="0" velocity="1"/>
  </joint>

  <link
    name="YL">
    <visual>
      <origin
        xyz="0 0 0"
        rpy="0 0 0" />
      <geometry>
        <mesh
          filename="file:///home/ben/scara_ws/src/scara_description/YL.STL" />
      </geometry>
      <material
        name="">
        <color
          rgba="0.792156862745098 0.819607843137255 0.933333333333333 1" />
      </material>
    </visual>
    <collision>
      <origin
        xyz="0 0 0"
        rpy="0 0 0" />
      <geometry>
        <mesh
          filename="file:///home/ben/scara_ws/src/scara_description/YL.STL" />
      </geometry>
    </collision>
  </link>

  <joint
    name="YJ"
    type="revolute">
    <origin
      xyz="0.17822 0.0243 -0.21159"
      rpy="-1.5708 -0.72393 0" />
    <parent
      link="XL" />
    <child
      link="YL" />
    <axis
      xyz="0 0 1" />
<limit effort="1000.0" lower="-4.5" upper="1.5" velocity="1"/>
  </joint>

  <link
    name="AL">
    <visual>
      <origin
        xyz="0 0 0"
        rpy="0 0 -2.6335" />
      <geometry>
        <mesh
          filename="file:///home/ben/scara_ws/src/scara_description/AL.STL" />
      </geometry>
      <material
        name="">
        <color
          rgba="0.792156862745098 0.819607843137255 0.933333333333333 1" />
      </material>
    </visual>
    <collision>
      <origin
        xyz="0 0 0"
        rpy="0 0 -2.6335" />
      <geometry>
        <mesh
          filename="file:///home/ben/scara_ws/src/scara_description/AL.STL" />
      </geometry>
    </collision>
  </link>

  <joint
    name="AJ"
    type="revolute">
    <origin
      xyz="-0.18889 -0.036901 0.0473"
      rpy="0 0 0" />
    <parent
      link="YL" />
    <child
      link="AL" />
    <axis
      xyz="0 0 1" />
 <limit effort="1000.0" lower="-2.5" upper="2.5" velocity="1"/>
  </joint>

  <link
    name="jaw0">
    <visual>
      <origin
        xyz="0 0 0"
        rpy="0 0 0" />
      <geometry>
        <mesh
          filename="file:///home/ben/scara_ws/src/scara_description/jaw0.STL" />
      </geometry>
      <material
        name="">
        <color
          rgba="0.792156862745098 0.819607843137255 0.933333333333333 1" />
      </material>
    </visual>
    <collision>
      <origin
        xyz="0 0 0"
        rpy="0 0 0" />
      <geometry>
        <mesh
          filename="file:///home/ben/scara_ws/src/scara_description/jaw0.STL" />
      </geometry>
    </collision>
  </link>

  <joint
    name="G0"
    type="prismatic">
    <origin
      xyz="0 0 -0.0844"
      rpy="3.1416 0 0" />
    <parent
      link="AL" />
    <child
      link="jaw0" />
    <axis
      xyz="0 1 0" />
 <limit effort="1000.0" lower="0" upper="0.05" velocity="1000"/>
</joint>

  <link
    name="jaw1">
    <visual>
      <origin
        xyz="0 0 0"
        rpy="0 0 0" />
      <geometry>
        <mesh
          filename="file:///home/ben/scara_ws/src/scara_description/jaw1.STL" />
      </geometry>
      <material
        name="">
        <color
          rgba="0.792156862745098 0.819607843137255 0.933333333333333 1" />
      </material>
    </visual>
    <collision>
      <origin
        xyz="0 0 0"
        rpy="0 0 0" />
      <geometry>
        <mesh
          filename="file:///home/ben/scara_ws/src/scara_description/jaw1.STL" />
      </geometry>
    </collision>
  </link>

  <joint
    name="G1"
    type="prismatic">
    <origin
      xyz="0 0 -0.0844"
      rpy="-3.1416 0 -1.5708" />
    <parent
      link="AL" />
    <child
      link="jaw1" />
    <axis
      xyz="-1 0 0" />
 <limit effort="1000.0" lower="0" upper="0.05" velocity="1000"/>
  </joint>
</robot>
